Workbook
Name __bookmark_2: TextTables!$A$1:$B$3805

Sheet ChangeLog
A1: ChangeLog
A2: 时间 | B2: Sheet | C2: 内容 | D2: 变更人
A3: 2025.08.07 | B3: Sys_ComIf ComRx_Bus SAM_Bus TCM_Bus CCM_Bus | C3: 1、"Sys_ComIf" #150：新增CAN接收信号CanRx_HvBattActSOC； 2、"ComRx_Bus" & “SAM_Bus” & “TCM_Bus” & “CCM_Bus” P列数据类型更新为带有前缀的； | D3: Mu Wenjie
A4: 2025.08.08 | B4: TextTables ADTTables | C4: 1、"TextTables" A列 & “ADTTables” B列名字分别添加“TMS_Enum_”和“TMS_ADT_”前缀； | D4: Mu Wenjie
A5: 2025.08.11 | B5: Sys_ComIf | C5: 1、"Sys_ComIf" G列模型信号名称删除前缀，保持和矩阵信号命名一致； | D5: Mu Wenjie
A6: 2025.08.19 | B6: Sys_ComIf | C6: 适配PufafengUIM接口更新模型接口 | D6: LS
A7: 2025.08.20 | B7: Sys_ComIf | C7: 新增占位接口 OccupantStsFL OccupantStsFR OccupantStsRL OccupantStsRM OccupantStsRR | D7: LS
A8: 2025.08.20 | B8: Sys_ComIf | C8: 新增TCM_Bus TCM_DfgType TCM_CabMode_FL TCM_CabMode_FR TCM_DesPwr TCM_HeatSource_Cab | D8: LS
A9: 2025.08.20 | B9: Sys_ComIf | C9: 新增AC充电信号 ACChrgSt ACChrgnHndlSts | D9: LS
A10: 2025.08.25 | B10: Sys_IoIf | C10: 新增19个RCP专用输入接口（温度传感器原始电阻kΩ，数据类型默认是double），适配RCP直接采样传感器电阻值，亦方便ASW直接进行RT值转换。 | D10: Mu Wenjie
A11: 2025.08.25 | B11: UIM_Bus | C11: 删除： HMI_MaxHeatDsp_Fr HMI_MaxACDsp_Rr HMI_MaxHeatDsp_Rr 新增： HMI_OutletMode_FL HMI_OutletModeDsp_FL | D11: LS
A12: 2025.08.29 | B12: ADTTables | C12: #2列的TMS_ADT_Perc1的无符号fixdt(0,16,0.1,0)改成有符号fixdt(1,16,0.1,0)。 | D12: Mu Wenjie
A13: 2025.09.01 | B13: SenCorr_Bus SysReq_Bus ComRx_Bus | C13: 1、新增2个bus：“SenCorr_Bus”&“SysReq_Bus”； 2、新增"ComRx_Bus" 中#213~253行UIM相关CAN输入（橘色部分）； | D13: Mu Wenjie
... A22: 2025.11.06 | B22: ComRx_Bus | C22: 随DBC变更 新增以下接口 Cal_Sig_CooltT1Ena Cal_Sig_CooltT1 Cal_Sig_CooltT2Ena Cal_Sig_CooltT2 Cal_Sig_CooltT3Ena Cal_Sig_CooltT3 | D22: Linhongyi Sheng

Sheet Sys_ComIf
A1: No | B1: Request type | C1: Net | D1: Direction | E1: Mode Name | F1: Signal Short Name | G1: Model Signal Name | H1: BSW Name | I1: Signal Length(Bit) | J1: Signal Type | K1: Signal Initial Value | L1: Signal Range | M1: Signal Conversion | N1: Data Type | O1: InitialValue | P1: Alias Data Type | Q1: Min | R1: Max | S1: Factor | T1: Offset | U1: Value Range | V1: Unit | W1: Enumerations | X1: Comment | Y1: XCP_Sig | Z1: EnumCheck | AA1: 是否在SDB中
D2: Tx | F2: HMI_HMISts_Fr | G2: HMI_HMISts_Fr | I2: =VLOOKUP(F2, '[1]Can Matrix'!$M:$X, 2, FALSE) -> 8 | J2: =IF(I2<=8,"uint8",IF(I2<=16,"uint16","uint32")) -> uint8 | M2: ='[1]Can Matrix'!$R$2 -> Unsigned | N2: =IFERROR(IF(VLOOKUP(F2, '[1]Can Matrix'!$M:$X, 12, FALSE) = 0, "", VLOOKUP(F2, '[1]Can Matrix'!$M:$X, 12, FALSE)), "") | X2: 0x0：Init 0x1：Manu 0x2：Auto 0x3：FastVent 0x4：MaxDef 0x5：MaxAC 0x6：MaxHeat 0x7：SmartClear 0x8：Off 0x9：PowerOff | Z2: =IF(N2="", "", IF(ISNUMBER(MATCH(N2, TextTables!A:A, 0)), "Y", "N")) | AA2: =IF(ISNUMBER(MATCH(F2, '[1]Can Matrix'!M:M, 0)), "Y", "N") -> Y
D3: TX | F3: HMI_HMISts_Rr | G3: HMI_HMISts_Rr | I3: =VLOOKUP(F3, '[1]Can Matrix'!$M:$X, 2, FALSE) -> 8 | J3: =IF(I3<=8,"uint8",IF(I3<=16,"uint16","uint32")) -> uint8 | M3: ='[1]Can Matrix'!$R$2 -> Unsigned | N3: =IFERROR(IF(VLOOKUP(F3, '[1]Can Matrix'!$M:$X, 12, FALSE)=0, "", "TMS_Enum_" & VLOOKUP(F3, '[1]Can Matrix'!$M:$X, 12, FALSE)), "") | X3: 0x0：Init 0x1：Manu 0x2：Auto 0x3：FastVent 0x4：MaxDef 0x5：MaxAC 0x6：MaxHeat 0x7：SmartClear 0x8：Off 0x9：PowerOff | Z3: =IF(N3="", "", IF(ISNUMBER(MATCH(N3, TextTables!A:A, 0)), "Y", "N")) | AA3: =IF(ISNUMBER(MATCH(F3, '[1]Can Matrix'!M:M, 0)), "Y", "N") -> Y
D4: TX | F4: HMI_HMIOnSts_Fr | G4: HMI_HMIOnSts_Fr | I4: =VLOOKUP(F4, '[1]Can Matrix'!$M:$X, 2, FALSE) -> 1 | J4: =IF(I4<=8,"uint8",IF(I4<=16,"uint16","uint32")) -> uint8 | M4: ='[1]Can Matrix'!$R$2 -> Unsigned | N4: =IFERROR(IF(VLOOKUP(F4, '[1]Can Matrix'!$M:$X, 12, FALSE)=0, "", "TMS_Enum_" & VLOOKUP(F4, '[1]Can Matrix'!$M:$X, 12, FALSE)), "") | X4: 0x0：Off 0x1：On | Z4: =IF(N4="", "", IF(ISNUMBER(MATCH(N4, TextTables!A:A, 0)), "Y", "N")) | AA4: =IF(ISNUMBER(MATCH(F4, '[1]Can Matrix'!M:M, 0)), "Y", "N") -> Y
D5: TX | F5: HMI_HMIOnSts_Rr | G5: HMI_HMIOnSts_Rr | I5: =VLOOKUP(F5, '[1]Can Matrix'!$M:$X, 2, FALSE) -> 1 | J5: =IF(I5<=8,"uint8",IF(I5<=16,"uint16","uint32")) -> uint8 | M5: ='[1]Can Matrix'!$R$2 -> Unsigned | N5: =IFERROR(IF(VLOOKUP(F5, '[1]Can Matrix'!$M:$X, 12, FALSE)=0, "", "TMS_Enum_" & VLOOKUP(F5, '[1]Can Matrix'!$M:$X, 12, FALSE)), "") | X5: 0x0：Off 0x1：On | Z5: =IF(N5="", "", IF(ISNUMBER(MATCH(N5, TextTables!A:A, 0)), "Y", "N")) | AA5: =IF(ISNUMBER(MATCH(F5, '[1]Can Matrix'!M:M, 0)), "Y", "N") -> Y
D6: TX | F6: HMI_OnOffDsp_Fr | G6: HMI_OnOffDsp_Fr | I6: =VLOOKUP(F6, '[1]Can Matrix'!$M:$X, 2, FALSE) -> 8 | J6: =IF(I6<=8,"uint8",IF(I6<=16,"uint16","uint32")) -> uint8 | M6: ='[1]Can Matrix'!$R$2 -> Unsigned | N6: =IFERROR(IF(VLOOKUP(F6, '[1]Can Matrix'!$M:$X, 12, FALSE)=0, "", "TMS_Enum_" & VLOOKUP(F6, '[1]Can Matrix'!$M:$X, 12, FALSE)), "") | X6: 0x0：Off 0x1：On | Z6: =IF(N6="", "", IF(ISNUMBER(MATCH(N6, TextTables!A:A, 0)), "Y", "N")) | AA6: =IF(ISNUMBER(MATCH(F6, '[1]Can Matrix'!M:M, 0)), "Y", "N") -> Y
D7: TX | F7: HMI_OnOffDsp_Rr | G7: HMI_OnOffDsp_Rr | I7: =VLOOKUP(F7, '[1]Can Matrix'!$M:$X, 2, FALSE) -> 8 | J7: =IF(I7<=8,"uint8",IF(I7<=16,"uint16","uint32")) -> uint8 | M7: ='[1]Can Matrix'!$R$2 -> Unsigned | N7: =IFERROR(IF(VLOOKUP(F7, '[1]Can Matrix'!$M:$X, 12, FALSE)=0, "", "TMS_Enum_" & VLOOKUP(F7, '[1]Can Matrix'!$M:$X, 12, FALSE)), "") | X7: 0x0：Off 0x1：On | Z7: =IF(N7="", "", IF(ISNUMBER(MATCH(N7, TextTables!A:A, 0)), "Y", "N")) | AA7: =IF(ISNUMBER(MATCH(F7, '[1]Can Matrix'!M:M, 0)), "Y", "N") -> Y
D8: TX | F8: HMI_AutoManuDsp_Fr | G8: HMI_AutoManuDsp_Fr | I8: =VLOOKUP(F8, '[1]Can Matrix'!$M:$X, 2, FALSE) -> 8 | J8: =IF(I8<=8,"uint8",IF(I8<=16,"uint16","uint32")) -> uint8 | M8: ='[1]Can Matrix'!$R$2 -> Unsigned | N8: =IFERROR(IF(VLOOKUP(F8, '[1]Can Matrix'!$M:$X, 12, FALSE)=0, "", "TMS_Enum_" & VLOOKUP(F8, '[1]Can Matrix'!$M:$X, 12, FALSE)), "") | X8: 0x0：Auto 0x1：Not Auto | Z8: =IF(N8="", "", IF(ISNUMBER(MATCH(N8, TextTables!A:A, 0)), "Y", "N")) | AA8: =IF(ISNUMBER(MATCH(F8, '[1]Can Matrix'!M:M, 0)), "Y", "N") -> Y
D9: TX | F9: HMI_AutoManuDsp_Rr | G9: HMI_AutoManuDsp_Rr | I9: =VLOOKUP(F9, '[1]Can Matrix'!$M:$X, 2, FALSE) -> 8 | J9: =IF(I9<=8,"uint8",IF(I9<=16,"uint16","uint32")) -> uint8 | M9: ='[1]Can Matrix'!$R$2 -> Unsigned | N9: =IFERROR(IF(VLOOKUP(F9, '[1]Can Matrix'!$M:$X, 12, FALSE)=0, "", "TMS_Enum_" & VLOOKUP(F9, '[1]Can Matrix'!$M:$X, 12, FALSE)), "") | X9: 0x0：Auto 0x1：Not Auto | Z9: =IF(N9="", "", IF(ISNUMBER(MATCH(N9, TextTables!A:A, 0)), "Y", "N")) | AA9: =IF(ISNUMBER(MATCH(F9, '[1]Can Matrix'!M:M, 0)), "Y", "N") -> Y
D10: TX | F10: HMI_MaxDefDsp | G10: HMI_MaxDefDsp | I10: =VLOOKUP(F10, '[1]Can Matrix'!$M:$X, 2, FALSE) -> 8 | J10: =IF(I10<=8,"uint8",IF(I10<=16,"uint16","uint32")) -> uint8 | M10: ='[1]Can Matrix'!$R$2 -> Unsigned | N10: =IFERROR(IF(VLOOKUP(F10, '[1]Can Matrix'!$M:$X, 12, FALSE)=0, "", "TMS_Enum_" & VLOOKUP(F10, '[1]Can Matrix'!$M:$X, 12, FALSE)), "") | X10: 0x0：Off 0x1：On | Z10: =IF(N10="", "", IF(ISNUMBER(MATCH(N10, TextTables!A:A, 0)), "Y", "N")) | AA10: =IF(ISNUMBER(MATCH(F10, '[1]Can Matrix'!M:M, 0)), "Y", "N") -> Y
D11: TX | F11: HMI_MaxACDsp_Fr | G11: HMI_MaxACDsp_Fr | I11: =VLOOKUP(F11, '[1]Can Matrix'!$M:$X, 2, FALSE) -> 8 | J11: =IF(I11<=8,"uint8",IF(I11<=16,"uint16","uint32")) -> uint8 | M11: ='[1]Can Matrix'!$R$2 -> Unsigned | N11: =IFERROR(IF(VLOOKUP(F11, '[1]Can Matrix'!$M:$X, 12, FALSE)=0, "", "TMS_Enum_" & VLOOKUP(F11, '[1]Can Matrix'!$M:$X, 12, FALSE)), "") | X11: 0x0：Off 0x1：On | Z11: =IF(N11="", "", IF(ISNUMBER(MATCH(N11, TextTables!A:A, 0)), "Y", "N")) | AA11: =IF(ISNUMBER(MATCH(F11, '[1]Can Matrix'!M:M, 0)), "Y", "N") -> Y
D12: TX | F12: HMI_MaxHeatDsp_Fr | G12: HMI_MaxHeatDsp_Fr | I12: =VLOOKUP(F12, '[1]Can Matrix'!$M:$X, 2, FALSE) -> 8 | J12: =IF(I12<=8,"uint8",IF(I12<=16,"uint16","uint32")) -> uint8 | M12: ='[1]Can Matrix'!$R$2 -> Unsigned | N12: =IFERROR(IF(VLOOKUP(F12, '[1]Can Matrix'!$M:$X, 12, FALSE)=0, "", "TMS_Enum_" & VLOOKUP(F12, '[1]Can Matrix'!$M:$X, 12, FALSE)), "") | X12: 0x0：Off 0x1：On | Z12: =IF(N12="", "", IF(ISNUMBER(MATCH(N12, TextTables!A:A, 0)), "Y", "N")) | AA12: =IF(ISNUMBER(MATCH(F12, '[1]Can Matrix'!M:M, 0)), "Y", "N") -> Y
D13: TX | F13: HMI_FastVentDsp | G13: HMI_FastVentDsp | I13: =VLOOKUP(F13, '[1]Can Matrix'!$M:$X, 2, FALSE) -> 8 | J13: =IF(I13<=8,"uint8",IF(I13<=16,"uint16","uint32")) -> uint8 | M13: ='[1]Can Matrix'!$R$2 -> Unsigned | N13: =IFERROR(IF(VLOOKUP(F13, '[1]Can Matrix'!$M:$X, 12, FALSE)=0, "", "TMS_Enum_" & VLOOKUP(F13, '[1]Can Matrix'!$M:$X, 12, FALSE)), "") | X13: 0x0：Off 0x1：On | Z13: =IF(N13="", "", IF(ISNUMBER(MATCH(N13, TextTables!A:A, 0)), "Y", "N")) | AA13: =IF(ISNUMBER(MATCH(F13, '[1]Can Matrix'!M:M, 0)), "Y", "N") -> Y
D14: TX | F14: HMI_MaxACDsp_Rr | G14: HMI_MaxACDsp_Rr | I14: =VLOOKUP(F14, '[1]Can Matrix'!$M:$X, 2, FALSE) -> 8 | J14: =IF(I14<=8,"uint8",IF(I14<=16,"uint16","uint32")) -> uint8 | M14: ='[1]Can Matrix'!$R$2 -> Unsigned | N14: =IFERROR(IF(VLOOKUP(F14, '[1]Can Matrix'!$M:$X, 12, FALSE)=0, "", "TMS_Enum_" & VLOOKUP(F14, '[1]Can Matrix'!$M:$X, 12, FALSE)), "") | X14: 0x0：Off 0x1：On | Z14: =IF(N14="", "", IF(ISNUMBER(MATCH(N14, TextTables!A:A, 0)), "Y", "N")) | AA14: =IF(ISNUMBER(MATCH(F14, '[1]Can Matrix'!M:M, 0)), "Y", "N") -> Y
... D27: TX | F27: HMI_VentDsp_Rr | G27: HMI_VentDsp_Rr | I27: =VLOOKUP(F27, '[1]Can Matrix'!$M:$X, 2, FALSE) -> 8 | J27: =IF(I27<=8,"uint8",IF(I27<=16,"uint16","uint32")) -> uint8 | M27: ='[1]Can Matrix'!$R$2 -> Unsigned | N27: =IFERROR(IF(VLOOKUP(F27, '[1]Can Matrix'!$M:$X, 12, FALSE)=0, "", "TMS_Enum_" & VLOOKUP(F27, '[1]Can Matrix'!$M:$X, 12, FALSE)), "") | X27: 0x0：Off 0x1：On | Z27: =IF(N27="", "", IF(ISNUMBER(MATCH(N27, TextTables!A:A, 0)), "Y", "N")) | AA27: =IF(ISNUMBER(MATCH(F27, '[1]Can Matrix'!M:M, 0)), "Y", "N") -> Y
D28: TX | F28: HMI_TSet_FL | G28: HMI_TSet_FL | I28: =VLOOKUP(F28, '[1]Can Matrix'!$M:$X, 2, FALSE) -> 16 | J28: =IF(I28<=8,"uint8",IF(I28<=16,"uint16","uint32")) -> uint16 | M28: ='[1]Can Matrix'!$R$2 -> Unsigned | N28: =IFERROR(IF(VLOOKUP(F28, '[1]Can Matrix'!$M:$X, 12, FALSE)=0, "", "TMS_Enum_" & VLOOKUP(F28, '[1]Can Matrix'!$M:$X, 12, FALSE)), "") | Z28: =IF(N28="", "", IF(ISNUMBER(MATCH(N28, TextTables!A:A, 0)), "Y", "N")) | AA28: =IF(ISNUMBER(MATCH(F28, '[1]Can Matrix'!M:M, 0)), "Y", "N") -> Y
D29: TX | F29: HMI_TSet_FR | G29: HMI_TSet_FR | I29: =VLOOKUP(F29, '[1]Can Matrix'!$M:$X, 2, FALSE) -> 16 | J29: =IF(I29<=8,"uint8",IF(I29<=16,"uint16","uint32")) -> uint16 | M29: ='[1]Can Matrix'!$R$2 -> Unsigned | N29: =IFERROR(IF(VLOOKUP(F29, '[1]Can Matrix'!$M:$X, 12, FALSE)=0, "", "TMS_Enum_" & VLOOKUP(F29, '[1]Can Matrix'!$M:$X, 12, FALSE)), "") | Z29: =IF(N29="", "", IF(ISNUMBER(MATCH(N29, TextTables!A:A, 0)), "Y", "N")) | AA29: =IF(ISNUMBER(MATCH(F29, '[1]Can Matrix'!M:M, 0)), "Y", "N") -> Y
D30: TX | F30: HMI_TSet_Rr | G30: HMI_TSet_Rr | I30: =VLOOKUP(F30, '[1]Can Matrix'!$M:$X, 2, FALSE) -> 16 | J30: =IF(I30<=8,"uint8",IF(I30<=16,"uint16","uint32")) -> uint16 | M30: ='[1]Can Matrix'!$R$2 -> Unsigned | N30: =IFERROR(IF(VLOOKUP(F30, '[1]Can Matrix'!$M:$X, 12, FALSE)=0, "", "TMS_Enum_" & VLOOKUP(F30, '[1]Can Matrix'!$M:$X, 12, FALSE)), "") | Z30: =IF(N30="", "", IF(ISNUMBER(MATCH(N30, TextTables!A:A, 0)), "Y", "N")) | AA30: =IF(ISNUMBER(MATCH(F30, '[1]Can Matrix'!M:M, 0)), "Y", "N") -> Y
D31: TX | F31: HMI_TSetDsp_FL | G31: HMI_TSetDsp_FL | I31: =VLOOKUP(F31, '[1]Can Matrix'!$M:$X, 2, FALSE) -> 16 | J31: =IF(I31<=8,"uint8",IF(I31<=16,"uint16","uint32")) -> uint16 | M31: ='[1]Can Matrix'!$R$2 -> Unsigned | N31: =IFERROR(IF(VLOOKUP(F31, '[1]Can Matrix'!$M:$X, 12, FALSE)=0, "", "TMS_Enum_" & VLOOKUP(F31, '[1]Can Matrix'!$M:$X, 12, FALSE)), "") | Z31: =IF(N31="", "", IF(ISNUMBER(MATCH(N31, TextTables!A:A, 0)), "Y", "N")) | AA31: =IF(ISNUMBER(MATCH(F31, '[1]Can Matrix'!M:M, 0)), "Y", "N") -> Y
D32: TX | F32: HMI_TSetDsp_FR | G32: HMI_TSetDsp_FR | I32: =VLOOKUP(F32, '[1]Can Matrix'!$M:$X, 2, FALSE) -> 16 | J32: =IF(I32<=8,"uint8",IF(I32<=16,"uint16","uint32")) -> uint16 | M32: ='[1]Can Matrix'!$R$2 -> Unsigned | N32: =IFERROR(IF(VLOOKUP(F32, '[1]Can Matrix'!$M:$X, 12, FALSE)=0, "", "TMS_Enum_" & VLOOKUP(F32, '[1]Can Matrix'!$M:$X, 12, FALSE)), "") | Z32: =IF(N32="", "", IF(ISNUMBER(MATCH(N32, TextTables!A:A, 0)), "Y", "N")) | AA32: =IF(ISNUMBER(MATCH(F32, '[1]Can Matrix'!M:M, 0)), "Y", "N") -> Y
D33: TX | F33: HMI_TSetDsp_Rr | G33: HMI_TSetDsp_Rr | I33: =VLOOKUP(F33, '[1]Can Matrix'!$M:$X, 2, FALSE) -> 16 | J33: =IF(I33<=8,"uint8",IF(I33<=16,"uint16","uint32")) -> uint16 | M33: ='[1]Can Matrix'!$R$2 -> Unsigned | N33: =IFERROR(IF(VLOOKUP(F33, '[1]Can Matrix'!$M:$X, 12, FALSE)=0, "", "TMS_Enum_" & VLOOKUP(F33, '[1]Can Matrix'!$M:$X, 12, FALSE)), "") | Z33: =IF(N33="", "", IF(ISNUMBER(MATCH(N33, TextTables!A:A, 0)), "Y", "N")) | AA33: =IF(ISNUMBER(MATCH(F33, '[1]Can Matrix'!M:M, 0)), "Y", "N") -> Y
D34: TX | F34: HMI_WindLvl_FL | G34: HMI_WindLvl_FL | I34: =VLOOKUP(F34, '[1]Can Matrix'!$M:$X, 2, FALSE) -> 8 | J34: =IF(I34<=8,"uint8",IF(I34<=16,"uint16","uint32")) -> uint8 | M34: ='[1]Can Matrix'!$R$2 -> Unsigned | N34: =IFERROR(IF(VLOOKUP(F34, '[1]Can Matrix'!$M:$X, 12, FALSE)=0, "", "TMS_Enum_" & VLOOKUP(F34, '[1]Can Matrix'!$M:$X, 12, FALSE)), "") | X34: 0x0：Close 0x1：Level1 0x2：Level2 0x3：Level3 0x4：Level4 0x5：Level5 0x6：Level6 0x7：Level7 0x3E：MaxLevel 0x3F：Auto | Z34: =IF(N34="", "", IF(ISNUMBER(MATCH(N34, TextTables!A:A, 0)), "Y", "N")) | AA34: =IF(ISNUMBER(MATCH(F34, '[1]Can Matrix'!M:M, 0)), "Y", "N") -> Y
D35: TX | F35: HMI_WindLvl_FR | G35: HMI_WindLvl_FR | I35: =VLOOKUP(F35, '[1]Can Matrix'!$M:$X, 2, FALSE) -> 8 | J35: =IF(I35<=8,"uint8",IF(I35<=16,"uint16","uint32")) -> uint8 | M35: ='[1]Can Matrix'!$R$2 -> Unsigned | N35: =IFERROR(IF(VLOOKUP(F35, '[1]Can Matrix'!$M:$X, 12, FALSE)=0, "", "TMS_Enum_" & VLOOKUP(F35, '[1]Can Matrix'!$M:$X, 12, FALSE)), "") | X35: 0x0：Close 0x1：Level1 0x2：Level2 0x3：Level3 0x4：Level4 0x5：Level5 0x6：Level6 0x7：Level7 0x3E：MaxLevel 0x3F：Auto | Z35: =IF(N35="", "", IF(ISNUMBER(MATCH(N35, TextTables!A:A, 0)), "Y", "N")) | AA35: =IF(ISNUMBER(MATCH(F35, '[1]Can Matrix'!M:M, 0)), "Y", "N") -> Y
D36: TX | F36: HMI_WindLvl_Rr | G36: HMI_WindLvl_Rr | I36: =VLOOKUP(F36, '[1]Can Matrix'!$M:$X, 2, FALSE) -> 8 | J36: =IF(I36<=8,"uint8",IF(I36<=16,"uint16","uint32")) -> uint8 | M36: ='[1]Can Matrix'!$R$2 -> Unsigned | N36: =IFERROR(IF(VLOOKUP(F36, '[1]Can Matrix'!$M:$X, 12, FALSE)=0, "", "TMS_Enum_" & VLOOKUP(F36, '[1]Can Matrix'!$M:$X, 12, FALSE)), "") | X36: 0x0：Close 0x1：Level1 0x2：Level2 0x3：Level3 0x4：Level4 0x5：Level5 0x6：Level6 0x7：Level7 0x3E：MaxLevel 0x3F：Auto | Z36: =IF(N36="", "", IF(ISNUMBER(MATCH(N36, TextTables!A:A, 0)), "Y", "N")) | AA36: =IF(ISNUMBER(MATCH(F36, '[1]Can Matrix'!M:M, 0)), "Y", "N") -> Y
D37: TX | F37: HMI_WindLvlDsp_FL | G37: HMI_WindLvlDsp_FL | I37: =VLOOKUP(F37, '[1]Can Matrix'!$M:$X, 2, FALSE) -> 8 | J37: =IF(I37<=8,"uint8",IF(I37<=16,"uint16","uint32")) -> uint8 | M37: ='[1]Can Matrix'!$R$2 -> Unsigned | N37: =IFERROR(IF(VLOOKUP(F37, '[1]Can Matrix'!$M:$X, 12, FALSE)=0, "", "TMS_Enum_" & VLOOKUP(F37, '[1]Can Matrix'!$M:$X, 12, FALSE)), "") | X37: 0x0：Close 0x1：Level1 0x2：Level2 0x3：Level3 0x4：Level4 0x5：Level5 0x6：Level6 0x7：Level7 | Z37: =IF(N37="", "", IF(ISNUMBER(MATCH(N37, TextTables!A:A, 0)), "Y", "N")) | AA37: =IF(ISNUMBER(MATCH(F37, '[1]Can Matrix'!M:M, 0)), "Y", "N") -> Y
D38: TX | F38: HMI_WindLvlDsp_FR | G38: HMI_WindLvlDsp_FR | I38: =VLOOKUP(F38, '[1]Can Matrix'!$M:$X, 2, FALSE) -> 8 | J38: =IF(I38<=8,"uint8",IF(I38<=16,"uint16","uint32")) -> uint8 | M38: ='[1]Can Matrix'!$R$2 -> Unsigned | N38: =IFERROR(IF(VLOOKUP(F38, '[1]Can Matrix'!$M:$X, 12, FALSE)=0, "", "TMS_Enum_" & VLOOKUP(F38, '[1]Can Matrix'!$M:$X, 12, FALSE)), "") | X38: 0x0：Close 0x1：Level1 0x2：Level2 0x3：Level3 0x4：Level4 0x5：Level5 0x6：Level6 0x7：Level7 | Z38: =IF(N38="", "", IF(ISNUMBER(MATCH(N38, TextTables!A:A, 0)), "Y", "N")) | AA38: =IF(ISNUMBER(MATCH(F38, '[1]Can Matrix'!M:M, 0)), "Y", "N") -> Y
D39: TX | F39: HMI_WindLvlDsp_Rr | G39: HMI_WindLvlDsp_Rr | I39: =VLOOKUP(F39, '[1]Can Matrix'!$M:$X, 2, FALSE) -> 8 | J39: =IF(I39<=8,"uint8",IF(I39<=16,"uint16","uint32")) -> uint8 | M39: ='[1]Can Matrix'!$R$2 -> Unsigned | N39: =IFERROR(IF(VLOOKUP(F39, '[1]Can Matrix'!$M:$X, 12, FALSE)=0, "", "TMS_Enum_" & VLOOKUP(F39, '[1]Can Matrix'!$M:$X, 12, FALSE)), "") | X39: 0x0：Close 0x1：Level1 0x2：Level2 0x3：Level3 0x4：Level4 0x5：Level5 0x6：Level6 0x7：Level7 | Z39: =IF(N39="", "", IF(ISNUMBER(MATCH(N39, TextTables!A:A, 0)), "Y", "N")) | AA39: =IF(ISNUMBER(MATCH(F39, '[1]Can Matrix'!M:M, 0)), "Y", "N") -> Y
D40: TX | F40: HMI_OutletMode_Fr | G40: HMI_OutletMode_Fr | I40: =VLOOKUP(F40, '[1]Can Matrix'!$M:$X, 2, FALSE) -> 8 | J40: =IF(I40<=8,"uint8",IF(I40<=16,"uint16","uint32")) -> uint8 | M40: ='[1]Can Matrix'!$R$2 -> Unsigned | N40: =IFERROR(IF(VLOOKUP(F40, '[1]Can Matrix'!$M:$X, 12, FALSE)=0, "", "TMS_Enum_" & VLOOKUP(F40, '[1]Can Matrix'!$M:$X, 12, FALSE)), "") | X40: 0x0：Reserved 0x1：Face 0x2：Bilevel 0x3：Foot 0x4：FootDefrost 0x5：Defrost 0x6：FaceDefrost 0x7：FaceFootDefrost 0x3F：Auto | Z40: =IF(N40="", "", IF(ISNUMBER(MATCH(N40, TextTables!A:A, 0)), "Y", "N")) | AA40: =IF(ISNUMBER(MATCH(F40, '[1]Can Matrix'!M:M, 0)), "Y", "N") -> Y
D41: TX | F41: HMI_OutletMode_Rr | G41: HMI_OutletMode_Rr | I41: =VLOOKUP(F41, '[1]Can Matrix'!$M:$X, 2, FALSE) -> 8 | J41: =IF(I41<=8,"uint8",IF(I41<=16,"uint16","uint32")) -> uint8 | M41: ='[1]Can Matrix'!$R$2 -> Unsigned | N41: =IFERROR(IF(VLOOKUP(F41, '[1]Can Matrix'!$M:$X, 12, FALSE)=0, "", "TMS_Enum_" & VLOOKUP(F41, '[1]Can Matrix'!$M:$X, 12, FALSE)), "") | X41: 0x0：Reserved 0x1：Face 0x2：Bilevel 0x3：Foot 0x3F：Auto | Z41: =IF(N41="", "", IF(ISNUMBER(MATCH(N41, TextTables!A:A, 0)), "Y", "N")) | AA41: =IF(ISNUMBER(MATCH(F41, '[1]Can Matrix'!M:M, 0)), "Y", "N") -> Y
D42: TX | F42: HMI_OutletModeDsp_Fr | G42: HMI_OutletModeDsp_Fr | I42: =VLOOKUP(F42, '[1]Can Matrix'!$M:$X, 2, FALSE) -> 8 | J42: =IF(I42<=8,"uint8",IF(I42<=16,"uint16","uint32")) -> uint8 | M42: ='[1]Can Matrix'!$R$2 -> Unsigned | N42: =IFERROR(IF(VLOOKUP(F42, '[1]Can Matrix'!$M:$X, 12, FALSE)=0, "", "TMS_Enum_" & VLOOKUP(F42, '[1]Can Matrix'!$M:$X, 12, FALSE)), "") | X42: 0x0：Reserved 0x1：Face 0x2：Bilevel 0x3：Foot 0x4：FootDefrost 0x5：Defrost 0x6：FaceDefrost 0x7：FaceFootDefrost | Z42: =IF(N42="", "", IF(ISNUMBER(MATCH(N42, TextTables!A:A, 0)), "Y", "N")) | AA42: =IF(ISNUMBER(MATCH(F42, '[1]Can Matrix'!M:M, 0)), "Y", "N") -> Y
D43: TX | F43: HMI_OutletModeDsp_Rr | G43: HMI_OutletModeDsp_Rr | I43: =VLOOKUP(F43, '[1]Can Matrix'!$M:$X, 2, FALSE) -> 8 | J43: =IF(I43<=8,"uint8",IF(I43<=16,"uint16","uint32")) -> uint8 | M43: ='[1]Can Matrix'!$R$2 -> Unsigned | N43: =IFERROR(IF(VLOOKUP(F43, '[1]Can Matrix'!$M:$X, 12, FALSE)=0, "", "TMS_Enum_" & VLOOKUP(F43, '[1]Can Matrix'!$M:$X, 12, FALSE)), "") | X43: 0x0：Reserved 0x1：Face 0x2：Bilevel 0x3：Foot | Z43: =IF(N43="", "", IF(ISNUMBER(MATCH(N43, TextTables!A:A, 0)), "Y", "N")) | AA43: =IF(ISNUMBER(MATCH(F43, '[1]Can Matrix'!M:M, 0)), "Y", "N") -> Y
D44: TX | F44: HMI_Sync | G44: HMI_Sync | I44: =VLOOKUP(F44, '[1]Can Matrix'!$M:$X, 2, FALSE) -> 8 | J44: =IF(I44<=8,"uint8",IF(I44<=16,"uint16","uint32")) -> uint8 | M44: ='[1]Can Matrix'!$R$2 -> Unsigned | N44: =IFERROR(IF(VLOOKUP(F44, '[1]Can Matrix'!$M:$X, 12, FALSE)=0, "", "TMS_Enum_" & VLOOKUP(F44, '[1]Can Matrix'!$M:$X, 12, FALSE)), "") | X44: 0x0：Off 0x1：On | Z44: =IF(N44="", "", IF(ISNUMBER(MATCH(N44, TextTables!A:A, 0)), "Y", "N")) | AA44: =IF(ISNUMBER(MATCH(F44, '[1]Can Matrix'!M:M, 0)), "Y", "N") -> Y
D45: TX | F45: HMI_SyncDsp | G45: HMI_SyncDsp | I45: =VLOOKUP(F45, '[1]Can Matrix'!$M:$X, 2, FALSE) -> 8 | J45: =IF(I45<=8,"uint8",IF(I45<=16,"uint16","uint32")) -> uint8 | M45: ='[1]Can Matrix'!$R$2 -> Unsigned | N45: =IFERROR(IF(VLOOKUP(F45, '[1]Can Matrix'!$M:$X, 12, FALSE)=0, "", "TMS_Enum_" & VLOOKUP(F45, '[1]Can Matrix'!$M:$X, 12, FALSE)), "") | X45: 0x0：Off 0x1：On | Z45: =IF(N45="", "", IF(ISNUMBER(MATCH(N45, TextTables!A:A, 0)), "Y", "N")) | AA45: =IF(ISNUMBER(MATCH(F45, '[1]Can Matrix'!M:M, 0)), "Y", "N") -> Y
... D76: RX | F76: VentReq_RL | G76: VentReq_RL | I76: =VLOOKUP(F76, '[1]Can Matrix'!$M:$X, 2, FALSE) -> 8 | J76: =IF(I76<=8,"uint8",IF(I76<=16,"uint16","uint32")) -> uint8 | M76: ='[1]Can Matrix'!$R$2 -> Unsigned | N76: =IFERROR(IF(VLOOKUP(F76, '[1]Can Matrix'!$M:$X, 12, FALSE)=0, "", "TMS_Enum_" & VLOOKUP(F76, '[1]Can Matrix'!$M:$X, 12, FALSE)), "") | X76: 0x0：No Request 0x1：OFF 0x2：ON | Z76: =IF(N76="", "", IF(ISNUMBER(MATCH(N76, TextTables!A:A, 0)), "Y", "N")) | AA76: =IF(ISNUMBER(MATCH(F76, '[1]Can Matrix'!M:M, 0)), "Y", "N") -> Y
D77: RX | F77: TSet_FL | G77: TSet_FL | I77: =VLOOKUP(F77, '[1]Can Matrix'!$M:$X, 2, FALSE) -> 16 | J77: =IF(I77<=8,"uint8",IF(I77<=16,"uint16","uint32")) -> uint16 | M77: ='[1]Can Matrix'!$R$2 -> Unsigned | N77: =IFERROR(IF(VLOOKUP(F77, '[1]Can Matrix'!$M:$X, 12, FALSE)=0, "", "TMS_Enum_" & VLOOKUP(F77, '[1]Can Matrix'!$M:$X, 12, FALSE)), "") | Z77: =IF(N77="", "", IF(ISNUMBER(MATCH(N77, TextTables!A:A, 0)), "Y", "N")) | AA77: =IF(ISNUMBER(MATCH(F77, '[1]Can Matrix'!M:M, 0)), "Y", "N") -> Y
D78: RX | F78: TSet_FR | G78: TSet_FR | I78: =VLOOKUP(F78, '[1]Can Matrix'!$M:$X, 2, FALSE) -> 16 | J78: =IF(I78<=8,"uint8",IF(I78<=16,"uint16","uint32")) -> uint16 | M78: ='[1]Can Matrix'!$R$2 -> Unsigned | N78: =IFERROR(IF(VLOOKUP(F78, '[1]Can Matrix'!$M:$X, 12, FALSE)=0, "", "TMS_Enum_" & VLOOKUP(F78, '[1]Can Matrix'!$M:$X, 12, FALSE)), "") | Z78: =IF(N78="", "", IF(ISNUMBER(MATCH(N78, TextTables!A:A, 0)), "Y", "N")) | AA78: =IF(ISNUMBER(MATCH(F78, '[1]Can Matrix'!M:M, 0)), "Y", "N") -> Y
D79: RX | F79: TSet_RL | G79: TSet_RL | I79: =VLOOKUP(F79, '[1]Can Matrix'!$M:$X, 2, FALSE) -> 16 | J79: =IF(I79<=8,"uint8",IF(I79<=16,"uint16","uint32")) -> uint16 | M79: ='[1]Can Matrix'!$R$2 -> Unsigned | N79: =IFERROR(IF(VLOOKUP(F79, '[1]Can Matrix'!$M:$X, 12, FALSE)=0, "", "TMS_Enum_" & VLOOKUP(F79, '[1]Can Matrix'!$M:$X, 12, FALSE)), "") | Z79: =IF(N79="", "", IF(ISNUMBER(MATCH(N79, TextTables!A:A, 0)), "Y", "N")) | AA79: =IF(ISNUMBER(MATCH(F79, '[1]Can Matrix'!M:M, 0)), "Y", "N") -> Y
D80: RX | F80: WindLvl_FL | G80: WindLvl_FL | I80: =VLOOKUP(F80, '[1]Can Matrix'!$M:$X, 2, FALSE) -> 8 | J80: =IF(I80<=8,"uint8",IF(I80<=16,"uint16","uint32")) -> uint8 | M80: ='[1]Can Matrix'!$R$2 -> Unsigned | N80: =IFERROR(IF(VLOOKUP(F80, '[1]Can Matrix'!$M:$X, 12, FALSE)=0, "", "TMS_Enum_" & VLOOKUP(F80, '[1]Can Matrix'!$M:$X, 12, FALSE)), "") | X80: 0x0：No Request 0x1：Level1 0x2：Level2 0x3：Level3 0x4：Level4 0x5：Level5 0x6：Level6 0x7：Level7 | Z80: =IF(N80="", "", IF(ISNUMBER(MATCH(N80, TextTables!A:A, 0)), "Y", "N")) | AA80: =IF(ISNUMBER(MATCH(F80, '[1]Can Matrix'!M:M, 0)), "Y", "N") -> Y
D81: RX | F81: WindLvl_FR | G81: WindLvl_FR | I81: =VLOOKUP(F81, '[1]Can Matrix'!$M:$X, 2, FALSE) -> 8 | J81: =IF(I81<=8,"uint8",IF(I81<=16,"uint16","uint32")) -> uint8 | M81: ='[1]Can Matrix'!$R$2 -> Unsigned | N81: =IFERROR(IF(VLOOKUP(F81, '[1]Can Matrix'!$M:$X, 12, FALSE)=0, "", "TMS_Enum_" & VLOOKUP(F81, '[1]Can Matrix'!$M:$X, 12, FALSE)), "") | X81: 0x0：No Request 0x1：Level1 0x2：Level2 0x3：Level3 0x4：Level4 0x5：Level5 0x6：Level6 0x7：Level7 | Z81: =IF(N81="", "", IF(ISNUMBER(MATCH(N81, TextTables!A:A, 0)), "Y", "N")) | AA81: =IF(ISNUMBER(MATCH(F81, '[1]Can Matrix'!M:M, 0)), "Y", "N") -> Y
D82: RX | F82: WindLvl_RL | G82: WindLvl_RL | I82: =VLOOKUP(F82, '[1]Can Matrix'!$M:$X, 2, FALSE) -> 8 | J82: =IF(I82<=8,"uint8",IF(I82<=16,"uint16","uint32")) -> uint8 | M82: ='[1]Can Matrix'!$R$2 -> Unsigned | N82: =IFERROR(IF(VLOOKUP(F82, '[1]Can Matrix'!$M:$X, 12, FALSE)=0, "", "TMS_Enum_" & VLOOKUP(F82, '[1]Can Matrix'!$M:$X, 12, FALSE)), "") | X82: 0x0：No Request 0x1：Level1 0x2：Level2 0x3：Level3 0x4：Level4 0x5：Level5 0x6：Level6 0x7：Level7 | Z82: =IF(N82="", "", IF(ISNUMBER(MATCH(N82, TextTables!A:A, 0)), "Y", "N")) | AA82: =IF(ISNUMBER(MATCH(F82, '[1]Can Matrix'!M:M, 0)), "Y", "N") -> Y
...

Sheet ComRx_Bus
A1: No | B1: Request type | C1: Net | D1: Direction | E1: Mode Name | F1: Signal Short Name | G1: Model Signal Name | H1: BSW Name | I1: Signal Length(Bit) | J1: Signal Type | K1: Signal Initial Value | L1: Signal Range | M1: Signal Conversion | N1: Data Type | O1: InitialValue | P1: Alias Data Type | Q1: Min | R1: Max | S1: Factor | T1: Offset | U1: Value Range | V1: Unit | W1: Enumerations | X1: Comment | Y1: XCP_Sig | Z1: 是否在SDB中
D2: Rx | G2: ComRx_CmptmtFrntWindDewT | P2: TMS_ADT_T1
D3: Rx | G3: ComRx_CmptmtFrntWindT | P3: TMS_ADT_T1
D4: Rx | G4: ComRx_CmptmtRelHum | P4: TMS_ADT_Hum1
D5: Rx | G5: ComRx_RiSolarData | P5: uint16
D6: Rx | G6: ComRx_LeSolarData | P6: uint16
D7: Rx | G7: ComRx_VehSpd | P7: TMS_ADT_V1
D8: Rx | G8: ComRx_CarModSts | P8: Enum:TMS_Enum_CarModSts1
D9: Rx | G9: ComRx_UsgModSts | P9: Enum:TMS_Enum_UsgModSts1
D10: Rx | G10: ComRx_Cal_Sig_AmbTEna | P10: Enum:TMS_Enum_OnOff1
D11: Rx | G11: ComRx_Cal_Sig_AmbT | P11: TMS_ADT_T1
D12: Rx | G12: ComRx_Cal_Sig_InCarTEna | P12: Enum:TMS_Enum_OnOff1
D13: Rx | G13: ComRx_Cal_Sig_InCarT | P13: TMS_ADT_T1
... D261: Rx | G261: ComRx_ACChrgnHndlSts | P261: Enum:TMS_Enum_OnBdChrgrHndlSts

Sheet UIM_Bus
A1: No | B1: Request type | C1: Net | D1: Direction | E1: Mode Name | F1: Signal Short Name | G1: Model Signal Name | H1: BSW Name | I1: Signal Length(Bit) | J1: Signal Type | K1: Signal Initial Value | L1: Signal Range | M1: Signal Conversion | N1: Data Type | O1: InitialValue | P1: Alias Data Type | Q1: Min | R1: Max | S1: Factor | T1: Offset | U1: Value Range | V1: Unit | W1: Enumerations | X1: Comment | Y1: XCP_Sig | Z1: 是否在SDB中
G2: HMI_HMISts_Fr | O2: 0 | P2: uint8
G3: HMI_HMISts_Rr | O3: 0 | P3: uint8
G4: HMI_HMIOnSts_Fr | O4: 0 | P4: boolean
G5: HMI_HMIOnSts_Rr | O5: 0 | P5: boolean
G6: HMI_OnOffDsp_Fr | O6: 0 | P6: uint8
G7: HMI_OnOffDsp_Rr | O7: 0 | P7: uint8
G8: HMI_AutoManuDsp_Fr | O8: 0 | P8: uint8
G9: HMI_AutoManuDsp_Rr | O9: 0 | P9: uint8
G10: HMI_MaxDefDsp | O10: 0 | P10: uint8
G11: HMI_MaxACDsp_Fr | O11: 0 | P11: uint8
G12: HMI_MaxHeatDsp_Fr | O12: 0 | P12: uint8
G13: HMI_FastVentDsp | O13: 0 | P13: uint8
... G58: HMI_ACFrtPnlLckRrPnlDsp | O58: 0 | P58: uint8

Sheet SAM_Bus
A1: No | B1: Request type | C1: Net | D1: Direction | E1: Mode Name | F1: Signal Short Name | G1: Model Signal Name | H1: BSW Name | I1: Signal Length(Bit) | J1: Signal Type | K1: Signal Initial Value | L1: Signal Range | M1: Signal Conversion | N1: Data Type | O1: InitialValue | P1: Alias Data Type | Q1: Min | R1: Max | S1: Factor | T1: Offset | U1: Value Range | V1: Unit | W1: Enumerations | X1: Comment | Y1: XCP_Sig | Z1: 是否在SDB中
D2: Rx | G2: SAM_FrntBlwActSpd | P2: TMS_ADT_Rev1
D3: Rx | G3: SAM_ReBlwActSpd | P3: TMS_ADT_Rev1
D4: Rx | G4: SAM_FrntLeModMotActPosn | P4: TMS_ADT_Perc1
D5: Rx | G5: SAM_FrntRiModMotActPosn | P5: TMS_ADT_Perc1
D6: Rx | G6: SAM_FrntLeMixMotActPosn | P6: TMS_ADT_Perc1
D7: Rx | G7: SAM_FrntRiMixMotActPosn | P7: TMS_ADT_Perc1
D8: Rx | G8: SAM_OsaRecMotActPosn | P8: TMS_ADT_Perc1
D9: Rx | G9: SAM_ReLeModMotActPosn | P9: TMS_ADT_Perc1
D10: Rx | G10: SAM_ReLeMixMotActPosn | P10: TMS_ADT_Perc1
D11: Rx | G11: SAM_FrntCbnTFil | P11: TMS_ADT_T1
D12: Rx | G12: SAM_FrntHexTFil | P12: TMS_ADT_T1
D13: Rx | G13: SAM_FrntEvapTFil | P13: TMS_ADT_T1
... D88: Rx | G88: SAM_PmpRlyFltSts | P88: uint8

Sheet TCM_Bus
A1: No | B1: Request type | C1: Net | D1: Direction | E1: Mode Name | F1: Signal Short Name | G1: Model Signal Name | H1: BSW Name | I1: Signal Length(Bit) | J1: Signal Type | K1: Signal Initial Value | L1: Signal Range | M1: Signal Conversion | N1: Data Type | O1: InitialValue | P1: Alias Data Type | Q1: Min | R1: Max | S1: Factor | T1: Offset | U1: Value Range | V1: Unit | W1: Enumerations | X1: Comment | Y1: XCP_Sig | Z1: 是否在SDB中
B2: DDM/COM | D2: Tx | G2: TCM_HvBattPmpTarDuty | P2: TMS_ADT_Perc1
B3: DDM/COM | D3: Tx | G3: TCM_EldtPmpTarDuty | P3: TMS_ADT_Perc1
B4: DDM/COM | D4: Tx | G4: TCM_HeatrPmpTarDuty | P4: TMS_ADT_Perc1
B5: DDM | D5: Tx | G5: TCM_CoolgFanTarDuty | P5: TMS_ADT_Perc1
B6: DDM/COM | D6: Tx | G6: TCM_SOV1OnOffCmd | P6: Enum:TMS_Enum_OnOff1
B7: DDM/COM | D7: Tx | G7: TCM_SOV2OnOffCmd | P7: Enum:TMS_Enum_OnOff1
B8: DDM/COM | D8: Tx | G8: TCM_SOV3OnOffCmd | P8: Enum:TMS_Enum_OnOff1
B9: ACCM | D9: Tx | G9: TCM_CmprReqCmprPwrLim | P9: uint16
B10: ACCM | D10: Tx | G10: TCM_CmprReqCmprRunReq | P10: Enum:TMS_Enum_CmprRunReq
B11: ACCM | D11: Tx | G11: TCM_CmprReqCmprSpdReq | P11: TMS_ADT_Rev1
B12: HVCH | D12: Tx | G12: TCM_CooltFlowInCmptmtCirc | P12: TMS_ADT_Mf2 | X12: 制冷剂流量
B13: HVCH | D13: Tx | G13: TCM_HvCooltHeatrEnad | P13: boolean
B14: HVCH | D14: Tx | G14: TCM_HvWtrHeatrPwrCnsAllwd | P14: uint16
B15: HVCH | D15: Tx | G15: TCM_HvWtrHeatrWtrTDes | P15: TMS_ADT_T1
B16: AGM | D16: Tx | G16: TCM_GrlAutoCalibReq | P16: boolean
B17: AGM | D17: Tx | G17: TCM_GrlTrqBoostReq | P17: Enum:TMS_Enum_TorqueBoost
B18: AGM | D18: Tx | G18: TCM_GrlShttrDmdShttrCalEna | P18: Enum:TMS_Enum_ShttrCalEna
B19: AGM | D19: Tx | G19: TCM_GrlShttrDmdShttrPosnReq | P19: uint8
B20: EEXV | D20: Tx | G20: TCM_EexvPosnReqExvCalibReq | P20: Enum:TMS_Enum_ExvCalibReq
B21: EEXV | D21: Tx | G21: TCM_EexvPosnReqExvHeatdReq | P21: Enum:TMS_Enum_ExvHeatdReq | X21: exv加热请求
B22: EEXV | D22: Tx | G22: TCM_EexvPosnReqExvMovEnable | P22: Enum:TMS_Enum_ExvMovEnable
B23: EEXV | D23: Tx | G23: TCM_EexvPosnReqExvPosnReq | P23: TMS_ADT_Perc1
B24: BEXV | D24: Tx | G24: TCM_BexvPosnReqExvCalibReq | P24: Enum:TMS_Enum_ExvCalibReq
B25: BEXV | D25: Tx | G25: TCM_BexvPosnReqExvHeatdReq | P25: Enum:TMS_Enum_ExvHeatdReq
B26: BEXV | D26: Tx | G26: TCM_BexvPosnReqExvMovEnable | P26: Enum:TMS_Enum_ExvMovEnable
B27: BEXV | D27: Tx | G27: TCM_BexvPosnReqExvPosnReq | P27: TMS_ADT_Perc1
B28: CEXV | D28: Tx | G28: TCM_CexvPosnReqExvCalibReq | P28: Enum:TMS_Enum_ExvCalibReq
B29: CEXV | D29: Tx | G29: TCM_CexvPosnReqExvHeatdReq | P29: Enum:TMS_Enum_ExvHeatdReq
B30: CEXV | D30: Tx | G30: TCM_CexvPosnReqExvMovEnable | P30: Enum:TMS_Enum_ExvMovEnable
B31: CEXV | D31: Tx | G31: TCM_CexvPosnReqExvPosnReq | P31: TMS_ADT_Perc1
B32: BCTV | D32: Tx | G32: TCM_HpBattVlvActvSaveReq | P32: Enum:TMS_Enum_ActiveSaveReq | X32: 电源关闭前电池三通阀保存的阀位置
B33: BCTV | D33: Tx | G33: TCM_HpBattVlvPosSetReq | P33: TMS_ADT_Perc1 | X33: 电池三通阀位置请求
B34: BCTV | D34: Tx | G34: TCM_HpBattVlvRefDrvReq | P34: Enum:TMS_Enum_RefDrvReq | X34: 电池三通阀自学习请求
B35: BCTV | D35: Tx | G35: TCM_HpBattVlvSpdLvlReq | P35: Enum:TMS_Enum_SpdLvlReq | X35: 电池三通阀移动速度要求
B36: BCFV | D36: Tx | G36: TCM_HpBattFwvActvSaveReq | P36: Enum:TMS_Enum_ActiveSaveReq
B37: BCFV | D37: Tx | G37: TCM_HpBattFwvPosSetReq | P37: TMS_ADT_Perc1
B38: BCFV | D38: Tx | G38: TCM_HpBattFwvRefDrvReq | P38: Enum:TMS_Enum_RefDrvReq
B39: BCFV | D39: Tx | G39: TCM_HpBattFwvSpdLvlReq | P39: Enum:TMS_Enum_SpdLvlReq
B40: ECRV | D40: Tx | G40: TCM_EctvCmdVlvMovEna | P40: Enum:TMS_Enum_VlvMovEna
...

Sheet CCM_Bus
A1: No | B1: Request type | C1: Net | D1: Direction | E1: Mode Name | F1: Signal Short Name | G1: Model Signal Name | H1: BSW Name | I1: Signal Length(Bit) | J1: Signal Type | K1: Signal Initial Value | L1: Signal Range | M1: Signal Conversion | N1: Data Type | O1: InitialValue | P1: Alias Data Type | Q1: Min | R1: Max | S1: Factor | T1: Offset | U1: Value Range | V1: Unit | W1: Enumerations | X1: Comment | Y1: XCP_Sig | Z1: 是否在SDB中
B2: DDM | D2: Tx | G2: CCM_FrntBlwTgtDuty | P2: TMS_ADT_Perc1
B3: DDM/COM | D3: Tx | G3: CCM_FrntLeModMotTarPosn | P3: Enum:TMS_Enum_HmiCmptmtAirDistbnFrnt
B4: DDM/COM | D4: Tx | G4: CCM_FrntRiModMotTarPosn | P4: Enum:TMS_Enum_HmiCmptmtAirDistbnFrnt
B5: DDM/COM | D5: Tx | G5: CCM_FrntLeMixMotTarPosn | P5: TMS_ADT_Perc1
B6: DDM/COM | D6: Tx | G6: CCM_FrntRiMixMotTarPosn | P6: TMS_ADT_Perc1
B7: DDM/COM | D7: Tx | G7: CCM_OsaMotTarPosn | P7: TMS_ADT_Perc1
B8: DDM/COM | D8: Tx | G8: CCM_RecMotTarPosn | P8: TMS_ADT_Perc1
B9: DDM/COM | D9: Tx | G9: CCM_ReLeModMotTarPosn | P9: Enum:TMS_Enum_HmiCmptmtAirDistbnFrnt
B10: DDM/COM | D10: Tx | G10: CCM_ReRiModMotTarPosn | P10: Enum:TMS_Enum_HmiCmptmtAirDistbnFrnt
B11: DDM/COM | D11: Tx | G11: CCM_ReLeMixMotTarPosn | P11: TMS_ADT_Perc1
B12: DDM/COM | D12: Tx | G12: CCM_ReRiMixMotTarPosn | P12: TMS_ADT_Perc1
B13: DDM/COM | D13: Tx | G13: CCM_DefrstMotTarPosn | P13: TMS_ADT_Perc1
B14: COM | D14: Tx | G14: CCM_AutoDeHumPopUp | P14: Enum:TMS_Enum_ReqSts1 | X14: 弹出车厢自动除湿到HMI系统。
B15: COM | D15: Tx | G15: CCM_AutoDefrstPopUp | P15: Enum:TMS_Enum_ReqSts1 | X15: 自动除霜请求弹出。
B16: COM | D16: Tx | G16: CCM_AutoFreshPopUp | P16: Enum:TMS_Enum_ReqSts1 | X16: 自动循环请求弹出。
B17: COM | D17: Tx | G17: CCM_ClimaDefrstSts | P17: Enum:TMS_Enum_OnOff1
B18: COM | D18: Tx | G18: CCM_ClimaDefrstMaxSts | P18: boolean
B19: COM | D19: Tx | G19: CCM_HvacAirMFlwFrntEstimd | P19: TMS_ADT_Mf1 | X19: 质量风量
B20: COM | D20: Tx | G20: CCM_HvacAirMFlwReEstimd | P20: TMS_ADT_Mf1
B21: COM | D21: Tx | G21: CCM_HvacAirQFlwFrntEstimd | P21: uint16 | X21: 体积风量
B22: COM | D22: Tx | G22: CCM_HvacAirQFlwReEstimd | P22: uint16
B23: COM/TCM | D23: Tx | G23: CCM_HvacCoolgEnaFrnt | P23: Enum:TMS_Enum_OnOff1
B24: COM/TCM | D24: Tx | G24: CCM_HvacCoolgEnaRe | P24: Enum:TMS_Enum_OnOff1
B25: COM | D25: Tx | G25: CCM_HvacEvaprTSpFrnt | P25: TMS_ADT_T1 | X25: 目标蒸发器温度
B26: COM | D26: Tx | G26: CCM_HvacEvaprTSpRe | P26: TMS_ADT_T1
B27: COM | D27: Tx | G27: CCM_HvacRecircActRat | P27: TMS_ADT_Perc1
B28: COM/TCM | D28: Tx | G28: CCM_HvacTgtAirTForRowFirstLe | P28: TMS_ADT_T1 | X28: 目标出风温度
B29: COM/TCM | D29: Tx | G29: CCM_HvacTgtAirTForRowFirstRi | P29: TMS_ADT_T1
B30: COM/TCM | D30: Tx | G30: CCM_HvacTgtAirTForRowSecLe | P30: TMS_ADT_T1
B31: COM/TCM | D31: Tx | G31: CCM_HvacTgtAirTForRowSecRi | P31: TMS_ADT_T1
B32: COM/TCM | D32: Tx | G32: CCM_AmbTEstimdAmbTEstimd | P32: TMS_ADT_T1 | X32: 环境温度预估值
B33: COM/TCM | D33: Tx | G33: CCM_CmptmtTFrntCmptmtTFrnt | P33: TMS_ADT_T1 | X33: 前排车内温度
B34: COM/TCM | D34: Tx | G34: CCM_CmptmtTFrntFanForCmptmtTRunng | P34: Enum:TMS_Enum_Flg1 | X34: 前排车内温度风扇运转状态
B35: COM/TCM | D35: Tx | G35: CCM_CmptmtTReCmptmtTFrnt | P35: TMS_ADT_T1 | X35: 后排车内温度
B36: COM/TCM | D36: Tx | G36: CCM_CmptmtTReFanForCmptmtTRunng | P36: Enum:TMS_Enum_Flg1 | X36: 后排车内温度风扇运转状态
B37: COM/TCM | D37: Tx | G37: CCM_HvacCondsorTspFrntTHvac | P37: TMS_ADT_T1 | X37: 目标冷凝器温度
B38: COM/TCM | D38: Tx | G38: CCM_ClimaThermReq | P38: Enum:TMS_Enum_ModeCmptHp | X38: 热泵模式请求
B39: COM/TCM | D39: Tx | G39: CCM_ClimaThermSts | P39: Enum:TMS_Enum_ClimaSts | X39: 热泵模式状态
B40: COM/TCM | D40: Tx | G40: CCM_HvacAirTHvacIntkT | P40: TMS_ADT_T1 | X40: 进风温度计算
...

Sheet SenCorr_Bus
A1: No | B1: Request type | C1: Net | D1: Direction | E1: Mode Name | F1: Signal Short Name | G1: Model Signal Name | H1: BSW Name | I1: Signal Length(Bit) | J1: Signal Type | K1: Signal Initial Value | L1: Signal Range | M1: Signal Conversion | N1: Data Type | O1: InitialValue | P1: Alias Data Type | Q1: Min | R1: Max | S1: Factor | T1: Offset | U1: Value Range | V1: Unit | W1: Enumerations | X1: Comment | Y1: XCP_Sig | Z1: 是否在SDB中
D2: Tx | G2: SC_IncarT_FL | P2: DT_Tmp | X2: 主驾车内温度
D3: Tx | G3: SC_IncarT_FR | P3: DT_Tmp | X3: 副驾车内温度
D4: Tx | G4: SC_IncarT_Rr | P4: DT_Tmp | X4: 后排车内温度
D5: Tx | G5: SC_IncarT | P5: DT_Tmp | X5: 车内温度
D6: Tx | G6: SC_AirIntake_Fr | P6: DT_Tmp | X6: 前排进气温度
D7: Tx | G7: SC_AirIntake_Rr | P7: DT_Tmp | X7: 后排进气温度
D8: Tx | G8: SC_AmbT | P8: DT_Tmp | X8: 环境温度
D9: Tx | G9: SC_EvpT_Fr | P9: DT_Tmp | X9: 前蒸发器实际温度
D10: Tx | G10: SC_EvpT_Rr | P10: DT_Tmp | X10: 后蒸发器实际温度
D11: Tx | G11: SC_Solar_Lft | P11: uint16 | X11: 主驾阳光强度
D12: Tx | G12: SC_Solar_Rgt | P12: uint16 | X12: 副驾阳光强度
D13: Tx | G13: SC_DuctT_FL | P13: DT_Tmp | X13: 主驾风道温度
... D57: Tx | G57: SC_Current_Time | P57: uint32 | X57: 当前时间（用于记忆）
D58: Tx | G58: SC_AmbLevel | P58: Enum: EM_AmbLvl
D59: Tx | G59: SC_EvapSOVCloseFlg_Rr | P59: Enum: EM_LoadActStateMd
D60: Tx | G60: SC_DewPotTemp | P60: DT_Tmp
D61: Tx | G61: SC_FrWindTemp | P61: DT_Tmp
D62: Tx | G62: SC_FrWindRH | P62: DT_Tmp

Sheet SysReq_Bus
A1: No | B1: Request type | C1: Net | D1: Direction | E1: Mode Name | F1: Signal Short Name | G1: Model Signal Name | H1: BSW Name | I1: Signal Length(Bit) | J1: Signal Type | K1: Signal Initial Value | L1: Signal Range | M1: Signal Conversion | N1: Data Type | O1: InitialValue | P1: Alias Data Type | Q1: Min | R1: Max | S1: Factor | T1: Offset | U1: Value Range | V1: Unit | W1: Enumerations | X1: Comment | Y1: XCP_Sig | Z1: 是否在SDB中
D2: Tx | G2: SS_IGOnTime | P2: uint16 | X2: IG使能时间
D3: Tx | G3: SS_LVPwr_ON | P3: boolean | X3: 低压上电信号
D4: Tx | G4: SS_HVPwr_ON | P4: boolean | X4: 高压上电信号
D5: Tx | G5: SS_ChargeStatus | P5: uint8 | X5: 系统充放电状态
D6: Tx | G6: SS_VehicleType | P6: uint8 | X6: 车辆类型
D7: Tx | G7: SS_KeyOffClean | P7: boolean | X7: KeyOff清除信号
D8: Tx | G8: SS_ASWVersonA | P8: uint8 | X8: ASW版本号A-阶段
D9: Tx | G9: SS_ASWVersonB | P9: uint8 | X9: ASW版本号B-分支
D10: Tx | G10: SS_ASWVersonC | P10: uint8 | X10: ASW版本号C-版本
D11: Tx | G11: SS_ASWVerson | P11: uint16 | X11: ASW版本号-汇总
D12: Tx | G12: SS_HMIPwr_ON | P12: boolean | X12: HMI上电信号

Sheet Sys_IoIf
A1: No | B1: Request type | C1: Net | D1: Direction | E1: Mode Name | F1: Signal Short Name | G1: Model Signal Name | H1: ICD Name | I1: PIN脚 | J1: 所属芯片 | K1: Signal Length(Bit) | L1: Signal Type | M1: Signal Initial Value | N1: Signal Range | O1: Signal Conversion | P1: Data Type | Q1: InitialValue | R1: Alias Data Type | S1: Min | T1: Max | U1: Factor | V1: Offset | W1: Value Range | X1: Unit | Y1: Enumerations | Z1: Comment | AA1: XCP_Sig | AB1: BSW developer | AC1: BSW commment | AD1: 是否在SDB中
A2: 1 | C2: ZCUR | D2: Tx | G2: IoTx_FrntBlwPwmCmd_u16 | H2: FrntBlowerPwm | I2: J6_32 | J2: 4th_TLE75602 | K2: 16 | L2: uint16 | N2: 0-1000 | O2: 前排鼓风机PWM占空比请求 | Q2: 0 | R2: fixdt(0,16,0.1,0) | S2: 0 | T2: 100 | U2: 0.1 | V2: 0
A3: 2 | C3: ZCUR | D3: Tx | G3: IoTx_FrntBlwFrqCmd_u16 | K3: 16 | L3: uint16 | N3: 20-800 | O3: 前排鼓风机PWM频率请求 | Q3: 0 | S3: 20 | T3: 800 | U3: 1 | V3: 0
A4: 3 | C4: ZCUR | D4: Rx | G4: IoRx_FrntBlwPwmFlt_u8 | K4: 8 | L4: uint8 | N4: 0-255 | O4: 前排鼓风机PWM驱动端故障 | Q4: 0 | Z4: Bit0：SCB Bit1：SCG Bit2：OL
A5: 4 | C5: ZCUR | D5: Rx | G5: IoRx_FrntBlwFrqFb_u16 | H5: FrntBlowerPwmFb | I5: J2_20 | J5: #N/A | K5: 16 | L5: uint16 | N5: 0-800 | O5: 前排鼓风机频率反馈 | Q5: 0 | S5: 0 | T5: 800 | U5: 0.15 | V5: 0
A6: 5 | C6: ZCUR | D6: Tx | G6: IoTx_DCMot1RunDir_u8 | H6: HvacModFlapFrstRowLe + HvacModFlapFrstRowLe - | I6: J3_7 J3_24 | J6: 2nd TLE94112 | K6: 8 | L6: uint8 | N6: 0-3 | O6: Mot1驱动指令 | P6: MotRunCmd | Q6: 0 | S6: 0 | T6: 3 | U6: 1 | V6: 0 | Z6: 0 = Stop 1 = CW 2 = CCW 3 = Low Side Brake | AD6: Mot1：前左模式电机 Mot2：前右模式电机 Mot3：前左温度电机 Mot4：前右温度电机 Mot5：循环电机 Mot6：后左模式电机 Mot7：后左温度电机
A7: 6 | C7: ZCUR | D7: Tx | G7: IoTx_DCMot2RunDir_u8 | H7: HvacModFlapFrstRowRi + HvacModFlapFrstRowRi - | I7: J3_19 J3_4 | K7: 8 | L7: uint8 | N7: 0-3 | O7: Mot2驱动指令 | P7: MotRunCmd | Q7: 0 | S7: 0 | T7: 3 | U7: 1 | V7: 0
A8: 7 | C8: ZCUR | D8: Tx | G8: IoTx_DCMot3RunDir_u8 | H8: HvacTempFlapFrstRowLe + HvacTempFlapFrstRowLe - | I8: J3_6 J3_23 | K8: 8 | L8: uint8 | N8: 0-3 | O8: Mot3驱动指令 | P8: MotRunCmd | Q8: 0 | S8: 0 | T8: 3 | U8: 1 | V8: 0
A9: 8 | C9: ZCUR | D9: Tx | G9: IoTx_DCMot4RunDir_u8 | H9: HvacTempFlapFrstRowRi + HvacTempFlapFrstRowRi - | I9: J3_18 J3_20 | K9: 8 | L9: uint8 | N9: 0-3 | O9: Mot4驱动指令 | P9: MotRunCmd | Q9: 0 | S9: 0 | T9: 3 | U9: 1 | V9: 0
A10: 9 | C10: ZCUR | D10: Tx | G10: IoTx_DCMot5RunDir_u8 | H10: HvacRecircFlap + HvacRecircFlap - | I10: J1_43 J1_28 | J10: 1st TLE94112 | K10: 8 | L10: uint8 | N10: 0-3 | O10: Mot5驱动指令 | P10: MotRunCmd | Q10: 0 | S10: 0 | T10: 3 | U10: 1 | V10: 0
A11: 10 | C11: ZCUR | D11: Tx | G11: IoTx_DCMot6RunDir_u8 | H11: HvacModFlapSecRowLe + HvacModFlapSecRowLe - | I11: J3_8 J3_5 | J11: 2nd TLE94112 | K11: 8 | L11: uint8 | N11: 0-3 | O11: Mot6驱动指令 | P11: MotRunCmd | Q11: 0 | S11: 0 | T11: 3 | U11: 1 | V11: 0
A12: 11 | C12: ZCUR | D12: Tx | G12: IoTx_DCMot7RunDir_u8 | H12: HvacTempFlapSecRowLe + HvacTempFlapSecRowLe - | I12: J3_21 J3_22 | K12: 8 | L12: uint8 | N12: 0-3 | O12: Mot7驱动指令 | P12: MotRunCmd | Q12: 0 | S12: 0 | T12: 3 | U12: 1 | V12: 0
A13: 12 | C13: ZCUR | D13: Tx | G13: IoTx_DCMot1PwmCmd_u16 | H13: HvacModFlapFrstRowLe + HvacModFlapFrstRowLe - | I13: J3_7 J3_24 | J13: 2nd TLE94112 | K13: 16 | L13: uint16 | N13: 0-1000 | O13: Mot1PWM占空比请求 | Q13: 0 | R13: fixdt(0,16,0.1,0) | S13: 0 | T13: 100 | U13: 0.1 | V13: 0
A14: 13 | C14: ZCUR | D14: Tx | G14: IoTx_DCMot2PwmCmd_u16 | H14: HvacModFlapFrstRowRi + HvacModFlapFrstRowRi - | I14: J3_19 J3_4 | K14: 16 | L14: uint16 | N14: 0-1000 | O14: Mot2PWM占空比请求 | Q14: 0 | R14: fixdt(0,16,0.1,0) | S14: 0 | T14: 100 | U14: 0.1 | V14: 0
A15: 14 | C15: ZCUR | D15: Tx | G15: IoTx_DCMot3PwmCmd_u16 | H15: HvacTempFlapFrstRowLe + HvacTempFlapFrstRowLe - | I15: J3_6 J3_23 | K15: 16 | L15: uint16 | N15: 0-1000 | O15: Mot3PWM占空比请求 | Q15: 0 | R15: fixdt(0,16,0.1,0) | S15: 0 | T15: 100 | U15: 0.1 | V15: 0
A16: 15 | C16: ZCUR | D16: Tx | G16: IoTx_DCMot4PwmCmd_u16 | H16: HvacTempFlapFrstRowRi + HvacTempFlapFrstRowRi - | I16: J3_18 J3_20 | K16: 16 | L16: uint16 | N16: 0-1000 | O16: Mot4PWM占空比请求 | Q16: 0 | R16: fixdt(0,16,0.1,0) | S16: 0 | T16: 100 | U16: 0.1 | V16: 0
A17: 16 | C17: ZCUR | D17: Tx | G17: IoTx_DCMot5PwmCmd_u16 | H17: HvacRecircFlap + HvacRecircFlap - | I17: J1_43 J1_28 | J17: 1st TLE94112 | K17: 16 | L17: uint16 | N17: 0-1000 | O17: Mot5PWM占空比请求 | Q17: 0 | R17: fixdt(0,16,0.1,0) | S17: 0 | T17: 100 | U17: 0.1 | V17: 0
A18: 17 | C18: ZCUR | D18: Tx | G18: IoTx_DCMot6PwmCmd_u16 | H18: HvacModFlapSecRowLe + HvacModFlapSecRowLe - | I18: J3_8 J3_5 | J18: 2nd TLE94112 | K18: 16 | L18: uint16 | N18: 0-1000 | O18: Mot6PWM占空比请求 | Q18: 0 | R18: fixdt(0,16,0.1,0) | S18: 0 | T18: 100 | U18: 0.1 | V18: 0
A19: 18 | C19: ZCUR | D19: Tx | G19: IoTx_DCMot7PwmCmd_u16 | H19: HvacTempFlapSecRowLe + HvacTempFlapSecRowLe - | I19: J3_21 J3_22 | K19: 16 | L19: uint16 | N19: 0-1000 | O19: Mot7PWM占空比请求 | Q19: 0 | R19: fixdt(0,16,0.1,0) | S19: 0 | T19: 100 | U19: 0.1 | V19: 0
A20: 19 | C20: ZCUR | D20: Tx | G20: IoTx_DCMot1FrqCmd_u16 | H20: HvacModFlapFrstRowLe + HvacModFlapFrstRowLe - | I20: J3_7 J3_24 | J20: 2nd TLE94112 | K20: 16 | L20: uint16 | N20: 200 | O20: Mot1PWM频率请求 | Q20: 0 | S20: 200 | T20: 200 | U20: 1 | V20: 0
A21: 20 | C21: ZCUR | D21: Tx | G21: IoTx_DCMot2FrqCmd_u16 | H21: HvacModFlapFrstRowRi + HvacModFlapFrstRowRi - | I21: J3_19 J3_4 | K21: 16 | L21: uint16 | N21: 200 | O21: Mot2PWM频率请求 | Q21: 0 | S21: 200 | T21: 200 | U21: 1 | V21: 0
A22: 21 | C22: ZCUR | D22: Tx | G22: IoTx_DCMot3FrqCmd_u16 | H22: HvacTempFlapFrstRowLe + HvacTempFlapFrstRowLe - | I22: J3_6 J3_23 | K22: 16 | L22: uint16 | N22: 200 | O22: Mot3PWM频率请求 | Q22: 0 | S22: 200 | T22: 200 | U22: 1 | V22: 0
A23: 22 | C23: ZCUR | D23: Tx | G23: IoTx_DCMot4FrqCmd_u16 | H23: HvacTempFlapFrstRowRi + HvacTempFlapFrstRowRi - | I23: J3_18 J3_20 | K23: 16 | L23: uint16 | N23: 200 | O23: Mot4PWM频率请求 | Q23: 0 | S23: 200 | T23: 200 | U23: 1 | V23: 0
A24: 23 | C24: ZCUR | D24: Tx | G24: IoTx_DCMot5FrqCmd_u16 | H24: HvacRecircFlap + HvacRecircFlap - | I24: J1_43 J1_28 | J24: 1st TLE94112 | K24: 16 | L24: uint16 | N24: 200 | O24: Mot5PWM频率请求 | Q24: 0 | S24: 200 | T24: 200 | U24: 1 | V24: 0
A25: 24 | C25: ZCUR | D25: Tx | G25: IoTx_DCMot6FrqCmd_u16 | H25: HvacModFlapSecRowLe + HvacModFlapSecRowLe - | I25: J3_8 J3_5 | J25: 2nd TLE94112 | K25: 16 | L25: uint16 | N25: 200 | O25: Mot6PWM频率请求 | Q25: 0 | S25: 200 | T25: 200 | U25: 1 | V25: 0
A26: 25 | C26: ZCUR | D26: Tx | G26: IoTx_DCMot7FrqCmd_u16 | H26: HvacTempFlapSecRowLe + HvacTempFlapSecRowLe - | I26: J3_21 J3_22 | K26: 16 | L26: uint16 | N26: 200 | O26: Mot7PWM频率请求 | Q26: 0 | S26: 200 | T26: 200 | U26: 1 | V26: 0
A27: 26 | C27: ZCUR | D27: Rx | G27: IoRx_DCMot1ActVoltRaw_u16 | H27: HvacModFlapActlPosnFrstRowLe | I27: J3_48 | J27: #N/A | K27: 16 | L27: uint16 | N27: 0-5000 | O27: Mot1实际电压反馈 | Q27: 0 | S27: 0 | T27: 5000 | U27: 1 | V27: 0 | X27: mV | Z27: 引脚电压值
A28: 27 | C28: ZCUR | D28: Rx | G28: IoRx_DCMot2ActVoltRaw_u16 | H28: HvacModFlapActlPosnFrstRowRi | I28: J1_26 | J28: #N/A | K28: 16 | L28: uint16 | N28: 0-5000 | O28: Mot2实际电压反馈 | Q28: 0 | S28: 0 | T28: 5000 | U28: 1 | V28: 0 | X28: mV | Z28: 引脚电压值
A29: 28 | C29: ZCUR | D29: Rx | G29: IoRx_DCMot3ActVoltRaw_u16 | H29: HvacTempFlapActlPosnFrstRowLe | I29: J3_46 | J29: #N/A | K29: 16 | L29: uint16 | N29: 0-5000 | O29: Mot3实际电压反馈 | Q29: 0 | S29: 0 | T29: 5000 | U29: 1 | V29: 0 | X29: mV | Z29: 引脚电压值
A30: 29 | C30: ZCUR | D30: Rx | G30: IoRx_DCMot4ActVoltRaw_u16 | H30: HvacTempFlapActlPosnFrstRowRi | I30: J2_24 | J30: #N/A | K30: 16 | L30: uint16 | N30: 0-5000 | O30: Mot4实际电压反馈 | Q30: 0 | S30: 0 | T30: 5000 | U30: 1 | V30: 0 | X30: mV | Z30: 引脚电压值
A31: 30 | C31: ZCUR | D31: Rx | G31: IoRx_DCMot5ActVoltRaw_u16 | H31: HvacRecircFlapActlPosn | I31: J3_49 | J31: #N/A | K31: 16 | L31: uint16 | N31: 0-5000 | O31: Mot5实际电压反馈 | Q31: 0 | S31: 0 | T31: 5000 | U31: 1 | V31: 0 | X31: mV | Z31: 引脚电压值
A32: 31 | C32: ZCUR | D32: Rx | G32: IoRx_DCMot6ActVoltRaw_u16 | H32: HvacModFlapActlPosnSecRowLe | I32: J3_36 | J32: #N/A | K32: 16 | L32: uint16 | N32: 0-5000 | O32: Mot6实际电压反馈 | Q32: 0 | S32: 0 | T32: 5000 | U32: 1 | V32: 0 | X32: mV | Z32: 引脚电压值
A33: 32 | C33: ZCUR | D33: Rx | G33: IoRx_DCMot7ActVoltRaw_u16 | H33: HvacTempFlapActlPosnSecRowLe | I33: J3_34 | J33: #N/A | K33: 16 | L33: uint16 | N33: 0-5000 | O33: Mot7实际电压反馈 | Q33: 0 | S33: 0 | T33: 5000 | U33: 1 | V33: 0 | X33: mV | Z33: 引脚电压值
A34: 33 | C34: ZCUR | D34: Rx | G34: IoRx_DCMot1HbrFltFb_u8 | H34: HvacModFlapFrstRowLe + HvacModFlapFrstRowLe - | I34: J3_7 J3_24 | J34: 2nd TLE94112 | K34: 8 | L34: uint8 | N34: 0-255 | O34: Mot1H桥故障反馈 | Q34: 0 | Z34: Bit0：Open Bit1：Hbr1SCG Bit2：Hbr1SCB Bit3：Hbr2SCG Bit4：Hbr2SCB
A35: 34 | C35: ZCUR | D35: Rx | G35: IoRx_DCMot2HbrFltFb_u8 | H35: HvacModFlapFrstRowRi + HvacModFlapFrstRowRi - | I35: J3_19 J3_4 | K35: 8 | L35: uint8 | N35: 0-255 | O35: Mot2H桥故障反馈 | Q35: 0
A36: 35 | C36: ZCUR | D36: Rx | G36: IoRx_DCMot3HbrFltFb_u8 | H36: HvacTempFlapFrstRowLe + HvacTempFlapFrstRowLe - | I36: J3_6 J3_23 | K36: 8 | L36: uint8 | N36: 0-255 | O36: Mot3H桥故障反馈 | Q36: 0
A37: 36 | C37: ZCUR | D37: Rx | G37: IoRx_DCMot4HbrFltFb_u8 | H37: HvacTempFlapFrstRowRi + HvacTempFlapFrstRowRi - | I37: J3_18 J3_20 | K37: 8 | L37: uint8 | N37: 0-255 | O37: Mot4H桥故障反馈 | Q37: 0
A38: 37 | C38: ZCUR | D38: Rx | G38: IoRx_DCMot5HbrFltFb_u8 | H38: HvacRecircFlap + HvacRecircFlap - | I38: J1_43 J1_28 | J38: 1st TLE94112 | K38: 8 | L38: uint8 | N38: 0-255 | O38: Mot5H桥故障反馈 | Q38: 0
A39: 38 | C39: ZCUR | D39: Rx | G39: IoRx_DCMot6HbrFltFb_u8 | H39: HvacModFlapSecRowLe + HvacModFlapSecRowLe - | I39: J3_8 J3_5 | J39: 2nd TLE94112 | K39: 8 | L39: uint8 | N39: 0-255 | O39: Mot6H桥故障反馈 | Q39: 0
A40: 39 | C40: ZCUR | D40: Rx | G40: IoRx_DCMot7HbrFltFb_u8 | H40: HvacTempFlapSecRowLe + HvacTempFlapSecRowLe - | I40: J3_21 J3_22 | K40: 8 | L40: uint8 | N40: 0-255 | O40: Mot7H桥故障反馈 | Q40: 0
...

Sheet ADTTables
B1: 建议ADT名 | C1: Alias Data Type | D1: uint | E1: IntToPhy | F1: IDT | G1: Phy Min | H1: Phy Max | I1: comments
A2: 1 | B2: TMS_ADT_Rev1 | C2: fixdt(0,16,0.25,0) | D2: rpm | E2: *0.25 | F2: uint16 | G2: 0 | H2: 16383.75 | I2: 转速（压缩机/水泵/风扇/鼓风机）
A3: 2 | B3: TMS_ADT_Perc1 | C3: fixdt(1,16,0.1,0) | D3: % | E3: *0.1 | F3: uint16 | G3: -3276.8 | H3: 3276.7 | I3: 百分比
A4: 3 | B4: TMS_ADT_V1 | C4: fixdt(0,16,0.00391,0) | D4: m/s | E4: *0.00391 | F4: uint16 | G4: 0 | H4: 125.0027 | I4: 车速
A5: 4 | B5: TMS_ADT_U1 | C5: fixdt(0,16,0.001221,0) | D5: V | E5: *0.001221 | F5: uint16 | G5: 0 | H5: 5 | I5: 电压1（传感器等）
A6: 5 | B6: TMS_ADT_U2 | C6: fixdt(0,16,0.1,0) | D6: V | E6: *0.1 | F6: uint16 | G6: 0 | H6: 6553.5 | I6: 电压2
A7: 6 | B7: TMS_ADT_Mf1 | C7: fixdt(0,16,0.1,0) | D7: kg/h | E7: *0.1 | F7: uint16 | G7: 0 | H7: 6553.5 | I7: 质量流量1
A8: 7 | B8: TMS_ADT_Mf2 | C8: fixdt(0,16,0.05,0) | D8: L/min | E8: *0.05 | F8: uint16 | G8: NA | I8: 质量流量2
A9: 8 | B9: TMS_ADT_Curr1 | C9: fixdt(0,16,0.25,0) | D9: A | E9: *0.25 | F9: uint16 | G9: NA | I9: 电流1
A10: 9 | B10: TMS_ADT_Curr2 | C10: fixdt(0,16,0.1,0) | D10: A | E10: *0.1 | F10: uint16 | G10: NA | I10: 电流2
A11: 10 | B11: TMS_ADT_P1 | C11: fixdt(0,16,0.1,0) | D11: kPa | E11: *0.1 | F11: uint16 | G11: 0 | H11: 6553.5 | I11: 压力
A12: 11 | B12: TMS_ADT_T1 | C12: fixdt(1,16,0.1,-60) | D12: ℃ | E12: *0.1-60 | F12: sint16 | G12: -60 | H12: 200 | I12: 温度
A13: 12 | B13: TMS_ADT_De1 | C13: fixdt(0,32,0.0001,0) | D13: kg/m3 | E13: *0.0001 | F13: uint32 | G13: NA | I13: 密度
A14: 13 | B14: TMS_ADT_En1 | C14: fixdt(0,16,0.01,0) | D14: kJ/kg | E14: *0.01 | F14: uint16 | G14: 0 | H14: 655.35 | I14: 焓
A15: 14 | B15: TMS_ADT_CP1 | C15: fixdt(0,32,0.001,0) | D15: kJ/kgk | E15: *0.001 | F15: uint32 | I15: 比热
A16: 15 | B16: TMS_ADT_Hum1 | C16: fixdt(0,16,0.01,0) | D16: g/kg | E16: *0.01 | F16: uint16 | G16: 0 | H16: 100 | I16: 湿度
A17: 16 | B17: TMS_ADT_DT_Temp | C17: fixdt(0,16,0.1,0) | D17: ℃ | E17: *0.1 | F17: uint16 | G17: 0 | H17: 6535 | I17: 用户设定温度

Sheet TextTables
A1: Texttable | B1: Value
A2: TMS_Enum_AbsWarnIndcnReq | B2: 0 = AbsWarnIndcnReq_AbsWarnIndcnOnReq
A3: TMS_Enum_AbsWarnIndcnReq | B3: 1 = AbsWarnIndcnReq_AbsWarnIndcnFlsgReq
A4: TMS_Enum_AbsWarnIndcnReq | B4: 2 = AbsWarnIndcnReq_Resd2
A5: TMS_Enum_AbsWarnIndcnReq | B5: 3 = AbsWarnIndcnReq_AbsWarnIndcnOffReq
A6: TMS_Enum_AcHVoltResonanceStat | B6: 0 = AcHVoltResonanceStat_Normal
A7: TMS_Enum_AcHVoltResonanceStat | B7: 1 = AcHVoltResonanceStat_SpeedDecreased
A8: TMS_Enum_AcHVoltResonanceStat | B8: 2 = AcHVoltResonanceStat_Inoperative
A9: TMS_Enum_AcHVoltResonanceStat | B9: 3 = AcHVoltResonanceStat_Reserved
A10: TMS_Enum_ActiveSaveReq | B10: 0 = ActiveSaveReq_NoReq
A11: TMS_Enum_ActiveSaveReq | B11: 1 = ActiveSaveReq_ActiveSave_Req
A12: TMS_Enum_ActiveSaveReq | B12: 2 = ActiveSaveReq_Reserved
... A3839: TMS_Enum_ZoneId | B3839: 8 = ZoneId_kThirdRow
A3840: TMS_Enum_MotRunCmd | B3840: 0 = MotRunCmd_Stop | C3840: 停
A3841: TMS_Enum_MotRunCmd | B3841: 1 = MotRunCmd_CW | C3841: 正转
A3842: TMS_Enum_MotRunCmd | B3842: 2 = MotRunCmd_CCW | C3842: 反转
A3843: TMS_Enum_MotRunCmd | B3843: 3 = MotRunCmd_Low Side Brake | C3843: 刹车
